2020-01-21 08:47:18,158 INFO: Microblog startup [in /usr/src/app/app/__init__.py:51]
2020-01-23 01:27:54,325 ERROR: Exception on /edit_profile [POST] [in /usr/local/lib/python3.8/site-packages/flask/app.py:1890]
Traceback (most recent call last):
  File "/usr/local/lib/python3.8/site-packages/sqlalchemy/engine/base.py", line 1245, in _execute_context
    self.dialect.do_execute(
  File "/usr/local/lib/python3.8/site-packages/sqlalchemy/engine/default.py", line 581, in do_execute
    cursor.execute(statement, parameters)
sqlite3.IntegrityError: UNIQUE constraint failed: user.username

The above exception was the direct cause of the following exception:

Traceback (most recent call last):
  File "/usr/local/lib/python3.8/site-packages/flask/app.py", line 2446, in wsgi_app
    response = self.full_dispatch_request()
  File "/usr/local/lib/python3.8/site-packages/flask/app.py", line 1951, in full_dispatch_request
    rv = self.handle_user_exception(e)
  File "/usr/local/lib/python3.8/site-packages/flask/app.py", line 1820, in handle_user_exception
    reraise(exc_type, exc_value, tb)
  File "/usr/local/lib/python3.8/site-packages/flask/_compat.py", line 39, in reraise
    raise value
  File "/usr/local/lib/python3.8/site-packages/flask/app.py", line 1949, in full_dispatch_request
    rv = self.dispatch_request()
  File "/usr/local/lib/python3.8/site-packages/flask/app.py", line 1935, in dispatch_request
    return self.view_functions[rule.endpoint](**req.view_args)
  File "/usr/local/lib/python3.8/site-packages/flask_login/utils.py", line 261, in decorated_view
    return func(*args, **kwargs)
  File "/usr/src/app/app/routes.py", line 53, in edit_profile
    db.session.commit()
  File "/usr/local/lib/python3.8/site-packages/sqlalchemy/orm/scoping.py", line 162, in do
    return getattr(self.registry(), name)(*args, **kwargs)
  File "/usr/local/lib/python3.8/site-packages/sqlalchemy/orm/session.py", line 1036, in commit
    self.transaction.commit()
  File "/usr/local/lib/python3.8/site-packages/sqlalchemy/orm/session.py", line 503, in commit
    self._prepare_impl()
  File "/usr/local/lib/python3.8/site-packages/sqlalchemy/orm/session.py", line 482, in _prepare_impl
    self.session.flush()
  File "/usr/local/lib/python3.8/site-packages/sqlalchemy/orm/session.py", line 2479, in flush
    self._flush(objects)
  File "/usr/local/lib/python3.8/site-packages/sqlalchemy/orm/session.py", line 2617, in _flush
    transaction.rollback(_capture_exception=True)
  File "/usr/local/lib/python3.8/site-packages/sqlalchemy/util/langhelpers.py", line 68, in __exit__
    compat.reraise(exc_type, exc_value, exc_tb)
  File "/usr/local/lib/python3.8/site-packages/sqlalchemy/util/compat.py", line 153, in reraise
    raise value
  File "/usr/local/lib/python3.8/site-packages/sqlalchemy/orm/session.py", line 2577, in _flush
    flush_context.execute()
  File "/usr/local/lib/python3.8/site-packages/sqlalchemy/orm/unitofwork.py", line 422, in execute
    rec.execute(self)
  File "/usr/local/lib/python3.8/site-packages/sqlalchemy/orm/unitofwork.py", line 586, in execute
    persistence.save_obj(
  File "/usr/local/lib/python3.8/site-packages/sqlalchemy/orm/persistence.py", line 230, in save_obj
    _emit_update_statements(
  File "/usr/local/lib/python3.8/site-packages/sqlalchemy/orm/persistence.py", line 995, in _emit_update_statements
    c = cached_connections[connection].execute(
  File "/usr/local/lib/python3.8/site-packages/sqlalchemy/engine/base.py", line 982, in execute
    return meth(self, multiparams, params)
  File "/usr/local/lib/python3.8/site-packages/sqlalchemy/sql/elements.py", line 287, in _execute_on_connection
    return connection._execute_clauseelement(self, multiparams, params)
  File "/usr/local/lib/python3.8/site-packages/sqlalchemy/engine/base.py", line 1095, in _execute_clauseelement
    ret = self._execute_context(
  File "/usr/local/lib/python3.8/site-packages/sqlalchemy/engine/base.py", line 1249, in _execute_context
    self._handle_dbapi_exception(
  File "/usr/local/lib/python3.8/site-packages/sqlalchemy/engine/base.py", line 1476, in _handle_dbapi_exception
    util.raise_from_cause(sqlalchemy_exception, exc_info)
  File "/usr/local/lib/python3.8/site-packages/sqlalchemy/util/compat.py", line 398, in raise_from_cause
    reraise(type(exception), exception, tb=exc_tb, cause=cause)
  File "/usr/local/lib/python3.8/site-packages/sqlalchemy/util/compat.py", line 152, in reraise
    raise value.with_traceback(tb)
  File "/usr/local/lib/python3.8/site-packages/sqlalchemy/engine/base.py", line 1245, in _execute_context
    self.dialect.do_execute(
  File "/usr/local/lib/python3.8/site-packages/sqlalchemy/engine/default.py", line 581, in do_execute
    cursor.execute(statement, parameters)
sqlalchemy.exc.IntegrityError: (sqlite3.IntegrityError) UNIQUE constraint failed: user.username
[SQL: UPDATE user SET username=?, about_me=? WHERE user.id = ?]
[parameters: ('yeongyumin', 'aaaa', 4)]
(Background on this error at: http://sqlalche.me/e/gkpj)
2020-01-23 01:28:31,069 ERROR: Exception on /edit_profile [POST] [in /usr/local/lib/python3.8/site-packages/flask/app.py:1890]
Traceback (most recent call last):
  File "/usr/local/lib/python3.8/site-packages/sqlalchemy/engine/base.py", line 1245, in _execute_context
    self.dialect.do_execute(
  File "/usr/local/lib/python3.8/site-packages/sqlalchemy/engine/default.py", line 581, in do_execute
    cursor.execute(statement, parameters)
sqlite3.IntegrityError: UNIQUE constraint failed: user.username

The above exception was the direct cause of the following exception:

Traceback (most recent call last):
  File "/usr/local/lib/python3.8/site-packages/flask/app.py", line 2446, in wsgi_app
    response = self.full_dispatch_request()
  File "/usr/local/lib/python3.8/site-packages/flask/app.py", line 1951, in full_dispatch_request
    rv = self.handle_user_exception(e)
  File "/usr/local/lib/python3.8/site-packages/flask/app.py", line 1820, in handle_user_exception
    reraise(exc_type, exc_value, tb)
  File "/usr/local/lib/python3.8/site-packages/flask/_compat.py", line 39, in reraise
    raise value
  File "/usr/local/lib/python3.8/site-packages/flask/app.py", line 1949, in full_dispatch_request
    rv = self.dispatch_request()
  File "/usr/local/lib/python3.8/site-packages/flask/app.py", line 1935, in dispatch_request
    return self.view_functions[rule.endpoint](**req.view_args)
  File "/usr/local/lib/python3.8/site-packages/flask_login/utils.py", line 261, in decorated_view
    return func(*args, **kwargs)
  File "/usr/src/app/app/routes.py", line 53, in edit_profile
    db.session.commit()
  File "/usr/local/lib/python3.8/site-packages/sqlalchemy/orm/scoping.py", line 162, in do
    return getattr(self.registry(), name)(*args, **kwargs)
  File "/usr/local/lib/python3.8/site-packages/sqlalchemy/orm/session.py", line 1036, in commit
    self.transaction.commit()
  File "/usr/local/lib/python3.8/site-packages/sqlalchemy/orm/session.py", line 503, in commit
    self._prepare_impl()
  File "/usr/local/lib/python3.8/site-packages/sqlalchemy/orm/session.py", line 482, in _prepare_impl
    self.session.flush()
  File "/usr/local/lib/python3.8/site-packages/sqlalchemy/orm/session.py", line 2479, in flush
    self._flush(objects)
  File "/usr/local/lib/python3.8/site-packages/sqlalchemy/orm/session.py", line 2617, in _flush
    transaction.rollback(_capture_exception=True)
  File "/usr/local/lib/python3.8/site-packages/sqlalchemy/util/langhelpers.py", line 68, in __exit__
    compat.reraise(exc_type, exc_value, exc_tb)
  File "/usr/local/lib/python3.8/site-packages/sqlalchemy/util/compat.py", line 153, in reraise
    raise value
  File "/usr/local/lib/python3.8/site-packages/sqlalchemy/orm/session.py", line 2577, in _flush
    flush_context.execute()
  File "/usr/local/lib/python3.8/site-packages/sqlalchemy/orm/unitofwork.py", line 422, in execute
    rec.execute(self)
  File "/usr/local/lib/python3.8/site-packages/sqlalchemy/orm/unitofwork.py", line 586, in execute
    persistence.save_obj(
  File "/usr/local/lib/python3.8/site-packages/sqlalchemy/orm/persistence.py", line 230, in save_obj
    _emit_update_statements(
  File "/usr/local/lib/python3.8/site-packages/sqlalchemy/orm/persistence.py", line 995, in _emit_update_statements
    c = cached_connections[connection].execute(
  File "/usr/local/lib/python3.8/site-packages/sqlalchemy/engine/base.py", line 982, in execute
    return meth(self, multiparams, params)
  File "/usr/local/lib/python3.8/site-packages/sqlalchemy/sql/elements.py", line 287, in _execute_on_connection
    return connection._execute_clauseelement(self, multiparams, params)
  File "/usr/local/lib/python3.8/site-packages/sqlalchemy/engine/base.py", line 1095, in _execute_clauseelement
    ret = self._execute_context(
  File "/usr/local/lib/python3.8/site-packages/sqlalchemy/engine/base.py", line 1249, in _execute_context
    self._handle_dbapi_exception(
  File "/usr/local/lib/python3.8/site-packages/sqlalchemy/engine/base.py", line 1476, in _handle_dbapi_exception
    util.raise_from_cause(sqlalchemy_exception, exc_info)
  File "/usr/local/lib/python3.8/site-packages/sqlalchemy/util/compat.py", line 398, in raise_from_cause
    reraise(type(exception), exception, tb=exc_tb, cause=cause)
  File "/usr/local/lib/python3.8/site-packages/sqlalchemy/util/compat.py", line 152, in reraise
    raise value.with_traceback(tb)
  File "/usr/local/lib/python3.8/site-packages/sqlalchemy/engine/base.py", line 1245, in _execute_context
    self.dialect.do_execute(
  File "/usr/local/lib/python3.8/site-packages/sqlalchemy/engine/default.py", line 581, in do_execute
    cursor.execute(statement, parameters)
sqlalchemy.exc.IntegrityError: (sqlite3.IntegrityError) UNIQUE constraint failed: user.username
[SQL: UPDATE user SET username=?, about_me=? WHERE user.id = ?]
[parameters: ('yeongyumin', '???', 4)]
(Background on this error at: http://sqlalche.me/e/gkpj)
